<?xml version="1.0" ?>
<!-- =================================================================================== -->
<!-- |    This document was autogenerated by xacro from /home/bruno/catkin_ws/src/spider/spider_description/urdf/spider.xacro | -->
<!-- |    EDITING THIS FILE BY HAND IS NOT RECOMMENDED                                 | -->
<!-- =================================================================================== -->
<robot name="spider" xmlns:xacro="http://www.ros.org/wiki/xacro">
  <material name="black">
    <color rgba="0.0 0.0 0.0 1.0"/>
  </material>
  <material name="blue">
    <color rgba="0.0 0.0 0.8 1.0"/>
  </material>
  <material name="green">
    <color rgba="0.0 0.8 0.0 1.0"/>
  </material>
  <material name="gray">
    <color rgba="0.2 0.2 0.2 1.0"/>
  </material>
  <material name="orange">
    <color rgba="1.0 0.423529411765 0.0392156862745 1.0"/>
  </material>
  <material name="brown">
    <color rgba="0.870588235294 0.811764705882 0.764705882353 1.0"/>
  </material>
  <material name="red">
    <color rgba="0.8 0.0 0.0 1.0"/>
  </material>
  <material name="white">
    <color rgba="1.0 1.0 1.0 1.0"/>
  </material>
  <gazebo>
    <plugin filename="libgazebo_ros_control.so" name="gazebo_ros_control">
      <robotNamespace>/spider</robotNamespace>
    </plugin>
  </gazebo>
  <gazebo reference="body">
    <material>Gazebo/White</material>
  </gazebo>
  <gazebo reference="proximal_leg">
    <material>Gazebo/White</material>
  </gazebo>
  <gazebo reference="distal_leg">
    <material>Gazebo/White</material>
  </gazebo>
  <gazebo reference="a_servo">
    <material>Gazebo/Blue</material>
  </gazebo>
  <gazebo reference="b_servo">
    <material>Gazebo/Blue</material>
  </gazebo>
  <!-- Links -->
  <link name="base_link"/>
  <link name="body">
    <collision>
      <origin rpy="0 0 0" xyz="0 0 0"/>
      <geometry>
        <box size="0.15 0.1 0.05"/>
      </geometry>
    </collision>
    <visual>
      <origin rpy="0 0 0" xyz="0 0 0"/>
      <geometry>
        <box size="0.15 0.1 0.05"/>
      </geometry>
      <material name="white"/>
    </visual>
    <inertial>
      <mass value="0.5"/>
      <inertia ixx="0.000520833333333" ixy="0" ixz="0" iyy="0.00104166666667" iyz="0" izz="0.00104166666667"/>
    </inertial>
  </link>
  <link name="FL_a_servo">
    <collision>
      <origin rpy="0 0 0" xyz="0 0 0"/>
      <geometry>
        <box size="0.02 0.01 0.03"/>
      </geometry>
    </collision>
    <visual>
      <origin rpy="0 0 0" xyz="0 0 0"/>
      <geometry>
        <box size="0.02 0.01 0.03"/>
      </geometry>
      <material name="blue"/>
    </visual>
    <inertial>
      <mass value="0.009"/>
      <inertia ixx="1.0" ixy="0.0" ixz="0.0" iyy="1.0" iyz="0.0" izz="1.0"/>
    </inertial>
  </link>
  <link name="FL_b_servo">
    <collision>
      <origin rpy="0 0 0" xyz="0 0 0"/>
      <geometry>
        <box size="0.02 0.01 0.03"/>
      </geometry>
    </collision>
    <visual>
      <origin rpy="0 0 0" xyz="0 0 0"/>
      <geometry>
        <box size="0.02 0.01 0.03"/>
      </geometry>
      <material name="blue"/>
    </visual>
    <inertial>
      <mass value="0.009"/>
      <inertia ixx="7.5e-07" ixy="0" ixz="0" iyy="9.75e-07" iyz="0" izz="9.75e-07"/>
    </inertial>
  </link>
  <link name="FL_proximal_leg">
    <collision>
      <origin rpy="0 0 0" xyz="0 0 0.035"/>
      <geometry>
        <cylinder length="0.07" radius="0.005"/>
      </geometry>
    </collision>
    <visual>
      <origin rpy="0 0 0" xyz="0 0 0.035"/>
      <geometry>
        <cylinder length="0.07" radius="0.005"/>
      </geometry>
      <material name="white"/>
    </visual>
    <inertial>
      <mass value="0.05"/>
      <inertia ixx="1.0" ixy="0.0" ixz="0.0" iyy="1.0" iyz="0.0" izz="1.0"/>
    </inertial>
  </link>
  <link name="FL_distal_leg">
    <collision>
      <origin rpy="0 0 0" xyz="0 0 0.06"/>
      <geometry>
        <cylinder length="0.12" radius="0.005"/>
      </geometry>
    </collision>
    <visual>
      <origin rpy="0 0 0" xyz="0 0 0.06"/>
      <geometry>
        <cylinder length="0.12" radius="0.005"/>
      </geometry>
      <material name="white"/>
    </visual>
    <inertial>
      <mass value="0.05"/>
      <inertia ixx="1.0" ixy="0.0" ixz="0.0" iyy="1.0" iyz="0.0" izz="1.0"/>
    </inertial>
  </link>
  <joint name="FL_leg_fix" type="fixed">
    <parent link="body"/>
    <child link="FL_a_servo"/>
    <origin rpy="0 -1.57 1.57" xyz="0.075 0.06 0"/>
  </joint>
  <joint name="FL_a_joint" type="revolute">
    <parent link="FL_a_servo"/>
    <child link="FL_b_servo"/>
    <origin rpy="0 0 -1.57" xyz="0.015 0 -0.0075"/>
    <axis xyz="0 1 0"/>
    <limit effort="1" lower="-1.57" upper="1.57" velocity="3"/>
  </joint>
  <joint name="FL_b_joint" type="revolute">
    <parent link="FL_b_servo"/>
    <child link="FL_proximal_leg"/>
    <origin rpy="-1.57 0 0" xyz="0.0125 0 -0.0075"/>
    <axis xyz="1 0 0"/>
    <!-- Aqui esta el problema. Para un lado debe ser l=-3.14 y u=0 y para el otro l=0 y u=3.14 -->
    <limit effort="1000" lower="-3.14" upper="0.0" velocity="3"/>
  </joint>
  <joint name="FL_c_joint" type="revolute">
    <parent link="FL_proximal_leg"/>
    <child link="FL_distal_leg"/>
    <origin rpy="0 3.14 0" xyz="0 0.01 0.07"/>
    <axis xyz="1 0 0"/>
    <limit effort="1000" lower="-3.14" upper="0.0" velocity="3"/>
  </joint>
  <transmission name="FL_a_transmission">
    <type>transmission_interface/SimpleTransmission</type>
    <joint name="FL_a_joint">
      <hardwareInterface>PositionJointInterface</hardwareInterface>
    </joint>
    <actuator name="FL_a_joint_leg_actuator">
      <hardwareInterface>PositionJointInterface</hardwareInterface>
      <mechanicalReduction>10</mechanicalReduction>
    </actuator>
  </transmission>
  <transmission name="FL_b_transmission">
    <type>transmission_interface/SimpleTransmission</type>
    <joint name="FL_b_joint">
      <hardwareInterface>PositionJointInterface</hardwareInterface>
    </joint>
    <actuator name="FL_b_joint_leg_actuator">
      <hardwareInterface>PositionJointInterface</hardwareInterface>
      <mechanicalReduction>10</mechanicalReduction>
    </actuator>
  </transmission>
  <transmission name="FL_c_transmission">
    <type>transmission_interface/SimpleTransmission</type>
    <joint name="FL_c_joint">
      <hardwareInterface>PositionJointInterface</hardwareInterface>
    </joint>
    <actuator name="FL_c_joint_leg_actuator">
      <hardwareInterface>PositionJointInterface</hardwareInterface>
      <mechanicalReduction>10</mechanicalReduction>
    </actuator>
  </transmission>
  <link name="FR_a_servo">
    <collision>
      <origin rpy="0 0 0" xyz="0 0 0"/>
      <geometry>
        <box size="0.02 0.01 0.03"/>
      </geometry>
    </collision>
    <visual>
      <origin rpy="0 0 0" xyz="0 0 0"/>
      <geometry>
        <box size="0.02 0.01 0.03"/>
      </geometry>
      <material name="blue"/>
    </visual>
    <inertial>
      <mass value="0.009"/>
      <inertia ixx="1.0" ixy="0.0" ixz="0.0" iyy="1.0" iyz="0.0" izz="1.0"/>
    </inertial>
  </link>
  <link name="FR_b_servo">
    <collision>
      <origin rpy="0 0 0" xyz="0 0 0"/>
      <geometry>
        <box size="0.02 0.01 0.03"/>
      </geometry>
    </collision>
    <visual>
      <origin rpy="0 0 0" xyz="0 0 0"/>
      <geometry>
        <box size="0.02 0.01 0.03"/>
      </geometry>
      <material name="blue"/>
    </visual>
    <inertial>
      <mass value="0.009"/>
      <inertia ixx="7.5e-07" ixy="0" ixz="0" iyy="9.75e-07" iyz="0" izz="9.75e-07"/>
    </inertial>
  </link>
  <link name="FR_proximal_leg">
    <collision>
      <origin rpy="0 0 0" xyz="0 0 0.035"/>
      <geometry>
        <cylinder length="0.07" radius="0.005"/>
      </geometry>
    </collision>
    <visual>
      <origin rpy="0 0 0" xyz="0 0 0.035"/>
      <geometry>
        <cylinder length="0.07" radius="0.005"/>
      </geometry>
      <material name="white"/>
    </visual>
    <inertial>
      <mass value="0.05"/>
      <inertia ixx="1.0" ixy="0.0" ixz="0.0" iyy="1.0" iyz="0.0" izz="1.0"/>
    </inertial>
  </link>
  <link name="FR_distal_leg">
    <collision>
      <origin rpy="0 0 0" xyz="0 0 0.06"/>
      <geometry>
        <cylinder length="0.12" radius="0.005"/>
      </geometry>
    </collision>
    <visual>
      <origin rpy="0 0 0" xyz="0 0 0.06"/>
      <geometry>
        <cylinder length="0.12" radius="0.005"/>
      </geometry>
      <material name="white"/>
    </visual>
    <inertial>
      <mass value="0.05"/>
      <inertia ixx="1.0" ixy="0.0" ixz="0.0" iyy="1.0" iyz="0.0" izz="1.0"/>
    </inertial>
  </link>
  <joint name="FR_leg_fix" type="fixed">
    <parent link="body"/>
    <child link="FR_a_servo"/>
    <origin rpy="0 -1.57 -1.57" xyz="0.075 -0.06 0"/>
  </joint>
  <joint name="FR_a_joint" type="revolute">
    <parent link="FR_a_servo"/>
    <child link="FR_b_servo"/>
    <origin rpy="0 0 1.57" xyz="0.015 0 -0.0075"/>
    <axis xyz="0 1 0"/>
    <limit effort="1" lower="-1.57" upper="1.57" velocity="3"/>
  </joint>
  <joint name="FR_b_joint" type="revolute">
    <parent link="FR_b_servo"/>
    <child link="FR_proximal_leg"/>
    <origin rpy="1.57 0 0" xyz="0.0125 0 -0.0075"/>
    <axis xyz="1 0 0"/>
    <!-- Aqui esta el problema. Para un lado debe ser l=-3.14 y u=0 y para el otro l=0 y u=3.14 -->
    <limit effort="1000" lower="0.0" upper="3.14" velocity="3"/>
  </joint>
  <joint name="FR_c_joint" type="revolute">
    <parent link="FR_proximal_leg"/>
    <child link="FR_distal_leg"/>
    <origin rpy="0 3.14 0" xyz="0 -0.01 0.07"/>
    <axis xyz="1 0 0"/>
    <limit effort="1000" lower="0.0" upper="3.14" velocity="3"/>
  </joint>
  <transmission name="FR_a_transmission">
    <type>transmission_interface/SimpleTransmission</type>
    <joint name="FR_a_joint">
      <hardwareInterface>PositionJointInterface</hardwareInterface>
    </joint>
    <actuator name="FR_a_joint_leg_actuator">
      <hardwareInterface>PositionJointInterface</hardwareInterface>
      <mechanicalReduction>10</mechanicalReduction>
    </actuator>
  </transmission>
  <transmission name="FR_b_transmission">
    <type>transmission_interface/SimpleTransmission</type>
    <joint name="FR_b_joint">
      <hardwareInterface>PositionJointInterface</hardwareInterface>
    </joint>
    <actuator name="FR_b_joint_leg_actuator">
      <hardwareInterface>PositionJointInterface</hardwareInterface>
      <mechanicalReduction>10</mechanicalReduction>
    </actuator>
  </transmission>
  <transmission name="FR_c_transmission">
    <type>transmission_interface/SimpleTransmission</type>
    <joint name="FR_c_joint">
      <hardwareInterface>PositionJointInterface</hardwareInterface>
    </joint>
    <actuator name="FR_c_joint_leg_actuator">
      <hardwareInterface>PositionJointInterface</hardwareInterface>
      <mechanicalReduction>10</mechanicalReduction>
    </actuator>
  </transmission>
  <link name="ML_a_servo">
    <collision>
      <origin rpy="0 0 0" xyz="0 0 0"/>
      <geometry>
        <box size="0.02 0.01 0.03"/>
      </geometry>
    </collision>
    <visual>
      <origin rpy="0 0 0" xyz="0 0 0"/>
      <geometry>
        <box size="0.02 0.01 0.03"/>
      </geometry>
      <material name="blue"/>
    </visual>
    <inertial>
      <mass value="0.009"/>
      <inertia ixx="1.0" ixy="0.0" ixz="0.0" iyy="1.0" iyz="0.0" izz="1.0"/>
    </inertial>
  </link>
  <link name="ML_b_servo">
    <collision>
      <origin rpy="0 0 0" xyz="0 0 0"/>
      <geometry>
        <box size="0.02 0.01 0.03"/>
      </geometry>
    </collision>
    <visual>
      <origin rpy="0 0 0" xyz="0 0 0"/>
      <geometry>
        <box size="0.02 0.01 0.03"/>
      </geometry>
      <material name="blue"/>
    </visual>
    <inertial>
      <mass value="0.009"/>
      <inertia ixx="7.5e-07" ixy="0" ixz="0" iyy="9.75e-07" iyz="0" izz="9.75e-07"/>
    </inertial>
  </link>
  <link name="ML_proximal_leg">
    <collision>
      <origin rpy="0 0 0" xyz="0 0 0.035"/>
      <geometry>
        <cylinder length="0.07" radius="0.005"/>
      </geometry>
    </collision>
    <visual>
      <origin rpy="0 0 0" xyz="0 0 0.035"/>
      <geometry>
        <cylinder length="0.07" radius="0.005"/>
      </geometry>
      <material name="white"/>
    </visual>
    <inertial>
      <mass value="0.05"/>
      <inertia ixx="1.0" ixy="0.0" ixz="0.0" iyy="1.0" iyz="0.0" izz="1.0"/>
    </inertial>
  </link>
  <link name="ML_distal_leg">
    <collision>
      <origin rpy="0 0 0" xyz="0 0 0.06"/>
      <geometry>
        <cylinder length="0.12" radius="0.005"/>
      </geometry>
    </collision>
    <visual>
      <origin rpy="0 0 0" xyz="0 0 0.06"/>
      <geometry>
        <cylinder length="0.12" radius="0.005"/>
      </geometry>
      <material name="white"/>
    </visual>
    <inertial>
      <mass value="0.05"/>
      <inertia ixx="1.0" ixy="0.0" ixz="0.0" iyy="1.0" iyz="0.0" izz="1.0"/>
    </inertial>
  </link>
  <joint name="ML_leg_fix" type="fixed">
    <parent link="body"/>
    <child link="ML_a_servo"/>
    <origin rpy="0 -1.57 1.57" xyz="0.0 0.06 0"/>
  </joint>
  <joint name="ML_a_joint" type="revolute">
    <parent link="ML_a_servo"/>
    <child link="ML_b_servo"/>
    <origin rpy="0 0 -1.57" xyz="0.015 0 -0.0075"/>
    <axis xyz="0 1 0"/>
    <limit effort="1" lower="-1.57" upper="1.57" velocity="3"/>
  </joint>
  <joint name="ML_b_joint" type="revolute">
    <parent link="ML_b_servo"/>
    <child link="ML_proximal_leg"/>
    <origin rpy="-1.57 0 0" xyz="0.0125 0 -0.0075"/>
    <axis xyz="1 0 0"/>
    <!-- Aqui esta el problema. Para un lado debe ser l=-3.14 y u=0 y para el otro l=0 y u=3.14 -->
    <limit effort="1000" lower="-3.14" upper="0.0" velocity="3"/>
  </joint>
  <joint name="ML_c_joint" type="revolute">
    <parent link="ML_proximal_leg"/>
    <child link="ML_distal_leg"/>
    <origin rpy="0 3.14 0" xyz="0 0.01 0.07"/>
    <axis xyz="1 0 0"/>
    <limit effort="1000" lower="-3.14" upper="0.0" velocity="3"/>
  </joint>
  <transmission name="ML_a_transmission">
    <type>transmission_interface/SimpleTransmission</type>
    <joint name="ML_a_joint">
      <hardwareInterface>PositionJointInterface</hardwareInterface>
    </joint>
    <actuator name="ML_a_joint_leg_actuator">
      <hardwareInterface>PositionJointInterface</hardwareInterface>
      <mechanicalReduction>10</mechanicalReduction>
    </actuator>
  </transmission>
  <transmission name="ML_b_transmission">
    <type>transmission_interface/SimpleTransmission</type>
    <joint name="ML_b_joint">
      <hardwareInterface>PositionJointInterface</hardwareInterface>
    </joint>
    <actuator name="ML_b_joint_leg_actuator">
      <hardwareInterface>PositionJointInterface</hardwareInterface>
      <mechanicalReduction>10</mechanicalReduction>
    </actuator>
  </transmission>
  <transmission name="ML_c_transmission">
    <type>transmission_interface/SimpleTransmission</type>
    <joint name="ML_c_joint">
      <hardwareInterface>PositionJointInterface</hardwareInterface>
    </joint>
    <actuator name="ML_c_joint_leg_actuator">
      <hardwareInterface>PositionJointInterface</hardwareInterface>
      <mechanicalReduction>10</mechanicalReduction>
    </actuator>
  </transmission>
  <link name="MR_a_servo">
    <collision>
      <origin rpy="0 0 0" xyz="0 0 0"/>
      <geometry>
        <box size="0.02 0.01 0.03"/>
      </geometry>
    </collision>
    <visual>
      <origin rpy="0 0 0" xyz="0 0 0"/>
      <geometry>
        <box size="0.02 0.01 0.03"/>
      </geometry>
      <material name="blue"/>
    </visual>
    <inertial>
      <mass value="0.009"/>
      <inertia ixx="1.0" ixy="0.0" ixz="0.0" iyy="1.0" iyz="0.0" izz="1.0"/>
    </inertial>
  </link>
  <link name="MR_b_servo">
    <collision>
      <origin rpy="0 0 0" xyz="0 0 0"/>
      <geometry>
        <box size="0.02 0.01 0.03"/>
      </geometry>
    </collision>
    <visual>
      <origin rpy="0 0 0" xyz="0 0 0"/>
      <geometry>
        <box size="0.02 0.01 0.03"/>
      </geometry>
      <material name="blue"/>
    </visual>
    <inertial>
      <mass value="0.009"/>
      <inertia ixx="7.5e-07" ixy="0" ixz="0" iyy="9.75e-07" iyz="0" izz="9.75e-07"/>
    </inertial>
  </link>
  <link name="MR_proximal_leg">
    <collision>
      <origin rpy="0 0 0" xyz="0 0 0.035"/>
      <geometry>
        <cylinder length="0.07" radius="0.005"/>
      </geometry>
    </collision>
    <visual>
      <origin rpy="0 0 0" xyz="0 0 0.035"/>
      <geometry>
        <cylinder length="0.07" radius="0.005"/>
      </geometry>
      <material name="white"/>
    </visual>
    <inertial>
      <mass value="0.05"/>
      <inertia ixx="1.0" ixy="0.0" ixz="0.0" iyy="1.0" iyz="0.0" izz="1.0"/>
    </inertial>
  </link>
  <link name="MR_distal_leg">
    <collision>
      <origin rpy="0 0 0" xyz="0 0 0.06"/>
      <geometry>
        <cylinder length="0.12" radius="0.005"/>
      </geometry>
    </collision>
    <visual>
      <origin rpy="0 0 0" xyz="0 0 0.06"/>
      <geometry>
        <cylinder length="0.12" radius="0.005"/>
      </geometry>
      <material name="white"/>
    </visual>
    <inertial>
      <mass value="0.05"/>
      <inertia ixx="1.0" ixy="0.0" ixz="0.0" iyy="1.0" iyz="0.0" izz="1.0"/>
    </inertial>
  </link>
  <joint name="MR_leg_fix" type="fixed">
    <parent link="body"/>
    <child link="MR_a_servo"/>
    <origin rpy="0 -1.57 -1.57" xyz="0.0 -0.06 0"/>
  </joint>
  <joint name="MR_a_joint" type="revolute">
    <parent link="MR_a_servo"/>
    <child link="MR_b_servo"/>
    <origin rpy="0 0 1.57" xyz="0.015 0 -0.0075"/>
    <axis xyz="0 1 0"/>
    <limit effort="1" lower="-1.57" upper="1.57" velocity="3"/>
  </joint>
  <joint name="MR_b_joint" type="revolute">
    <parent link="MR_b_servo"/>
    <child link="MR_proximal_leg"/>
    <origin rpy="1.57 0 0" xyz="0.0125 0 -0.0075"/>
    <axis xyz="1 0 0"/>
    <!-- Aqui esta el problema. Para un lado debe ser l=-3.14 y u=0 y para el otro l=0 y u=3.14 -->
    <limit effort="1000" lower="0.0" upper="3.14" velocity="3"/>
  </joint>
  <joint name="MR_c_joint" type="revolute">
    <parent link="MR_proximal_leg"/>
    <child link="MR_distal_leg"/>
    <origin rpy="0 3.14 0" xyz="0 -0.01 0.07"/>
    <axis xyz="1 0 0"/>
    <limit effort="1000" lower="0.0" upper="3.14" velocity="3"/>
  </joint>
  <transmission name="MR_a_transmission">
    <type>transmission_interface/SimpleTransmission</type>
    <joint name="MR_a_joint">
      <hardwareInterface>PositionJointInterface</hardwareInterface>
    </joint>
    <actuator name="MR_a_joint_leg_actuator">
      <hardwareInterface>PositionJointInterface</hardwareInterface>
      <mechanicalReduction>10</mechanicalReduction>
    </actuator>
  </transmission>
  <transmission name="MR_b_transmission">
    <type>transmission_interface/SimpleTransmission</type>
    <joint name="MR_b_joint">
      <hardwareInterface>PositionJointInterface</hardwareInterface>
    </joint>
    <actuator name="MR_b_joint_leg_actuator">
      <hardwareInterface>PositionJointInterface</hardwareInterface>
      <mechanicalReduction>10</mechanicalReduction>
    </actuator>
  </transmission>
  <transmission name="MR_c_transmission">
    <type>transmission_interface/SimpleTransmission</type>
    <joint name="MR_c_joint">
      <hardwareInterface>PositionJointInterface</hardwareInterface>
    </joint>
    <actuator name="MR_c_joint_leg_actuator">
      <hardwareInterface>PositionJointInterface</hardwareInterface>
      <mechanicalReduction>10</mechanicalReduction>
    </actuator>
  </transmission>
  <link name="BL_a_servo">
    <collision>
      <origin rpy="0 0 0" xyz="0 0 0"/>
      <geometry>
        <box size="0.02 0.01 0.03"/>
      </geometry>
    </collision>
    <visual>
      <origin rpy="0 0 0" xyz="0 0 0"/>
      <geometry>
        <box size="0.02 0.01 0.03"/>
      </geometry>
      <material name="blue"/>
    </visual>
    <inertial>
      <mass value="0.009"/>
      <inertia ixx="1.0" ixy="0.0" ixz="0.0" iyy="1.0" iyz="0.0" izz="1.0"/>
    </inertial>
  </link>
  <link name="BL_b_servo">
    <collision>
      <origin rpy="0 0 0" xyz="0 0 0"/>
      <geometry>
        <box size="0.02 0.01 0.03"/>
      </geometry>
    </collision>
    <visual>
      <origin rpy="0 0 0" xyz="0 0 0"/>
      <geometry>
        <box size="0.02 0.01 0.03"/>
      </geometry>
      <material name="blue"/>
    </visual>
    <inertial>
      <mass value="0.009"/>
      <inertia ixx="7.5e-07" ixy="0" ixz="0" iyy="9.75e-07" iyz="0" izz="9.75e-07"/>
    </inertial>
  </link>
  <link name="BL_proximal_leg">
    <collision>
      <origin rpy="0 0 0" xyz="0 0 0.035"/>
      <geometry>
        <cylinder length="0.07" radius="0.005"/>
      </geometry>
    </collision>
    <visual>
      <origin rpy="0 0 0" xyz="0 0 0.035"/>
      <geometry>
        <cylinder length="0.07" radius="0.005"/>
      </geometry>
      <material name="white"/>
    </visual>
    <inertial>
      <mass value="0.05"/>
      <inertia ixx="1.0" ixy="0.0" ixz="0.0" iyy="1.0" iyz="0.0" izz="1.0"/>
    </inertial>
  </link>
  <link name="BL_distal_leg">
    <collision>
      <origin rpy="0 0 0" xyz="0 0 0.06"/>
      <geometry>
        <cylinder length="0.12" radius="0.005"/>
      </geometry>
    </collision>
    <visual>
      <origin rpy="0 0 0" xyz="0 0 0.06"/>
      <geometry>
        <cylinder length="0.12" radius="0.005"/>
      </geometry>
      <material name="white"/>
    </visual>
    <inertial>
      <mass value="0.05"/>
      <inertia ixx="1.0" ixy="0.0" ixz="0.0" iyy="1.0" iyz="0.0" izz="1.0"/>
    </inertial>
  </link>
  <joint name="BL_leg_fix" type="fixed">
    <parent link="body"/>
    <child link="BL_a_servo"/>
    <origin rpy="0 -1.57 1.57" xyz="-0.075 0.06 0"/>
  </joint>
  <joint name="BL_a_joint" type="revolute">
    <parent link="BL_a_servo"/>
    <child link="BL_b_servo"/>
    <origin rpy="0 0 -1.57" xyz="0.015 0 -0.0075"/>
    <axis xyz="0 1 0"/>
    <limit effort="1" lower="-1.57" upper="1.57" velocity="3"/>
  </joint>
  <joint name="BL_b_joint" type="revolute">
    <parent link="BL_b_servo"/>
    <child link="BL_proximal_leg"/>
    <origin rpy="-1.57 0 0" xyz="0.0125 0 -0.0075"/>
    <axis xyz="1 0 0"/>
    <!-- Aqui esta el problema. Para un lado debe ser l=-3.14 y u=0 y para el otro l=0 y u=3.14 -->
    <limit effort="1000" lower="-3.14" upper="0.0" velocity="3"/>
  </joint>
  <joint name="BL_c_joint" type="revolute">
    <parent link="BL_proximal_leg"/>
    <child link="BL_distal_leg"/>
    <origin rpy="0 3.14 0" xyz="0 0.01 0.07"/>
    <axis xyz="1 0 0"/>
    <limit effort="1000" lower="-3.14" upper="0.0" velocity="3"/>
  </joint>
  <transmission name="BL_a_transmission">
    <type>transmission_interface/SimpleTransmission</type>
    <joint name="BL_a_joint">
      <hardwareInterface>PositionJointInterface</hardwareInterface>
    </joint>
    <actuator name="BL_a_joint_leg_actuator">
      <hardwareInterface>PositionJointInterface</hardwareInterface>
      <mechanicalReduction>10</mechanicalReduction>
    </actuator>
  </transmission>
  <transmission name="BL_b_transmission">
    <type>transmission_interface/SimpleTransmission</type>
    <joint name="BL_b_joint">
      <hardwareInterface>PositionJointInterface</hardwareInterface>
    </joint>
    <actuator name="BL_b_joint_leg_actuator">
      <hardwareInterface>PositionJointInterface</hardwareInterface>
      <mechanicalReduction>10</mechanicalReduction>
    </actuator>
  </transmission>
  <transmission name="BL_c_transmission">
    <type>transmission_interface/SimpleTransmission</type>
    <joint name="BL_c_joint">
      <hardwareInterface>PositionJointInterface</hardwareInterface>
    </joint>
    <actuator name="BL_c_joint_leg_actuator">
      <hardwareInterface>PositionJointInterface</hardwareInterface>
      <mechanicalReduction>10</mechanicalReduction>
    </actuator>
  </transmission>
  <link name="BR_a_servo">
    <collision>
      <origin rpy="0 0 0" xyz="0 0 0"/>
      <geometry>
        <box size="0.02 0.01 0.03"/>
      </geometry>
    </collision>
    <visual>
      <origin rpy="0 0 0" xyz="0 0 0"/>
      <geometry>
        <box size="0.02 0.01 0.03"/>
      </geometry>
      <material name="blue"/>
    </visual>
    <inertial>
      <mass value="0.009"/>
      <inertia ixx="1.0" ixy="0.0" ixz="0.0" iyy="1.0" iyz="0.0" izz="1.0"/>
    </inertial>
  </link>
  <link name="BR_b_servo">
    <collision>
      <origin rpy="0 0 0" xyz="0 0 0"/>
      <geometry>
        <box size="0.02 0.01 0.03"/>
      </geometry>
    </collision>
    <visual>
      <origin rpy="0 0 0" xyz="0 0 0"/>
      <geometry>
        <box size="0.02 0.01 0.03"/>
      </geometry>
      <material name="blue"/>
    </visual>
    <inertial>
      <mass value="0.009"/>
      <inertia ixx="7.5e-07" ixy="0" ixz="0" iyy="9.75e-07" iyz="0" izz="9.75e-07"/>
    </inertial>
  </link>
  <link name="BR_proximal_leg">
    <collision>
      <origin rpy="0 0 0" xyz="0 0 0.035"/>
      <geometry>
        <cylinder length="0.07" radius="0.005"/>
      </geometry>
    </collision>
    <visual>
      <origin rpy="0 0 0" xyz="0 0 0.035"/>
      <geometry>
        <cylinder length="0.07" radius="0.005"/>
      </geometry>
      <material name="white"/>
    </visual>
    <inertial>
      <mass value="0.05"/>
      <inertia ixx="1.0" ixy="0.0" ixz="0.0" iyy="1.0" iyz="0.0" izz="1.0"/>
    </inertial>
  </link>
  <link name="BR_distal_leg">
    <collision>
      <origin rpy="0 0 0" xyz="0 0 0.06"/>
      <geometry>
        <cylinder length="0.12" radius="0.005"/>
      </geometry>
    </collision>
    <visual>
      <origin rpy="0 0 0" xyz="0 0 0.06"/>
      <geometry>
        <cylinder length="0.12" radius="0.005"/>
      </geometry>
      <material name="white"/>
    </visual>
    <inertial>
      <mass value="0.05"/>
      <inertia ixx="1.0" ixy="0.0" ixz="0.0" iyy="1.0" iyz="0.0" izz="1.0"/>
    </inertial>
  </link>
  <joint name="BR_leg_fix" type="fixed">
    <parent link="body"/>
    <child link="BR_a_servo"/>
    <origin rpy="0 -1.57 -1.57" xyz="-0.075 -0.06 0"/>
  </joint>
  <joint name="BR_a_joint" type="revolute">
    <parent link="BR_a_servo"/>
    <child link="BR_b_servo"/>
    <origin rpy="0 0 1.57" xyz="0.015 0 -0.0075"/>
    <axis xyz="0 1 0"/>
    <limit effort="1" lower="-1.57" upper="1.57" velocity="3"/>
  </joint>
  <joint name="BR_b_joint" type="revolute">
    <parent link="BR_b_servo"/>
    <child link="BR_proximal_leg"/>
    <origin rpy="1.57 0 0" xyz="0.0125 0 -0.0075"/>
    <axis xyz="1 0 0"/>
    <!-- Aqui esta el problema. Para un lado debe ser l=-3.14 y u=0 y para el otro l=0 y u=3.14 -->
    <limit effort="1000" lower="0.0" upper="3.14" velocity="3"/>
  </joint>
  <joint name="BR_c_joint" type="revolute">
    <parent link="BR_proximal_leg"/>
    <child link="BR_distal_leg"/>
    <origin rpy="0 3.14 0" xyz="0 -0.01 0.07"/>
    <axis xyz="1 0 0"/>
    <limit effort="1000" lower="0.0" upper="3.14" velocity="3"/>
  </joint>
  <transmission name="BR_a_transmission">
    <type>transmission_interface/SimpleTransmission</type>
    <joint name="BR_a_joint">
      <hardwareInterface>PositionJointInterface</hardwareInterface>
    </joint>
    <actuator name="BR_a_joint_leg_actuator">
      <hardwareInterface>PositionJointInterface</hardwareInterface>
      <mechanicalReduction>10</mechanicalReduction>
    </actuator>
  </transmission>
  <transmission name="BR_b_transmission">
    <type>transmission_interface/SimpleTransmission</type>
    <joint name="BR_b_joint">
      <hardwareInterface>PositionJointInterface</hardwareInterface>
    </joint>
    <actuator name="BR_b_joint_leg_actuator">
      <hardwareInterface>PositionJointInterface</hardwareInterface>
      <mechanicalReduction>10</mechanicalReduction>
    </actuator>
  </transmission>
  <transmission name="BR_c_transmission">
    <type>transmission_interface/SimpleTransmission</type>
    <joint name="BR_c_joint">
      <hardwareInterface>PositionJointInterface</hardwareInterface>
    </joint>
    <actuator name="BR_c_joint_leg_actuator">
      <hardwareInterface>PositionJointInterface</hardwareInterface>
      <mechanicalReduction>10</mechanicalReduction>
    </actuator>
  </transmission>
  <joint name="base_joint" type="fixed">
    <parent link="base_link"/>
    <child link="body"/>
  </joint>
</robot>

